/Users/kelseydoerksen/opt/anaconda3/envs/aq/lib/python3.10/site-packages/osgeo/gdal.py:312: FutureWarning: Neither gdal.UseExceptions() nor gdal.DontUseExceptions() has been explicitly called. In GDAL 4.0, exceptions will be enabled by default.
  warnings.warn(
Testing pre-trained model on latest Monsoon season...
Grabbing testing data...
> /Users/kelseydoerksen/code/landslide-forecast-nepal/unet/predict.py(38)predict()
     37
---> 38     loss_criterion = nn.BCEWithLogitsLoss()
     39     bce_score = 0
<torch.utils.data.dataloader.DataLoader object at 0x11e4cee30>
*** NameError: name 'inputs' is not defined
*** NameError: name 'labels' is not defined
*** NameError: name 'data' is not defined
<dataset.LandslideDataset object at 0x10da60190>
*** NameError: name 'outputs' is not defined
Traceback (most recent call last):
  File "/Users/kelseydoerksen/code/landslide-forecast-nepal/unet/run_pipeline.py", line 142, in <module>
    predict(unet, landslide_test_dataset, experiment, save_dir, device=device,
  File "/Users/kelseydoerksen/code/landslide-forecast-nepal/unet/predict.py", line 38, in predict
    loss_criterion = nn.BCEWithLogitsLoss()
  File "/Users/kelseydoerksen/code/landslide-forecast-nepal/unet/predict.py", line 38, in predict
    loss_criterion = nn.BCEWithLogitsLoss()
  File "/Users/kelseydoerksen/opt/anaconda3/envs/aq/lib/python3.10/bdb.py", line 90, in trace_dispatch
    return self.dispatch_line(frame)
  File "/Users/kelseydoerksen/opt/anaconda3/envs/aq/lib/python3.10/bdb.py", line 115, in dispatch_line
    if self.quitting: raise BdbQuit
bdb.BdbQuit
If you suspect this is an IPython 8.7.0 bug, please report it at:
    https://github.com/ipython/ipython/issues
or send an email to the mailing list at ipython-dev@python.org
You can print a more detailed traceback right now with "%tb", or use "%debug"
to interactively debug it.
Extra-detailed tracebacks for bug-reporting purposes can be enabled via:
    %config Application.verbose_crash=True