
Loading data...
Number of positive testing samples: 275
Number of negative testing samples: 1606
Fitting model...
Evaluating model...
The hard predictions were right 84.95% of the time
No Skill: ROC AUC=0.500
RFC: ROC AUC=0.806
The number of non-landslide events is: 1606
The number of landslide events is: 275
Best Threshold=0.170000, F-Score=0.459
/Users/kelseydoerksen/code/landslide-prediction/2024_Monsoon_Prep/run_classifier.py:107: RuntimeWarning: invalid value encountered in divide
  fscore = (2 * precision * recall) / (precision + recall)
> /Users/kelseydoerksen/code/landslide-prediction/2024_Monsoon_Prep/run_classifier.py(192)calc_model_performance()
    191     # --- Logging plots
--> 192     wandb_id.log({
    193         'roc at best threshold {}'.format(best_thresh): wandb.plot.roc_curve(labels, preds_1_and_0)
array([1, 0, 0, ..., 0, 0, 1])
7476     0
8190     0
9884     0
15337    1
8715     0
        ..
8967     0
14581    0
17332    0
14742    0
17381    0
Name: label, Length: 1881, dtype: int64
array([0, 0, 0, ..., 0, 0, 0])
*** TypeError: Singleton array array(1) cannot be considered a valid collection.
array([[0.79 , 0.21 ],
       [1.   , 0.   ],
       [0.86 , 0.14 ],
       ...,
       [0.85 , 0.15 ],
       [0.97 , 0.03 ],
       [0.775, 0.225]])
Traceback (most recent call last):
  File "/Users/kelseydoerksen/code/landslide-prediction/2024_Monsoon_Prep/run_classifier.py", line 391, in <module>
    run_rf(X_train, y_train, X_test, y_test, results, experiment)
  File "/Users/kelseydoerksen/code/landslide-prediction/2024_Monsoon_Prep/run_classifier.py", line 351, in run_rf
    calc_model_performance(forest, ytest, probs, Xtest, results, wandb_exp)
  File "/Users/kelseydoerksen/code/landslide-prediction/2024_Monsoon_Prep/run_classifier.py", line 192, in calc_model_performance
    wandb_id.log({
  File "/Users/kelseydoerksen/code/landslide-prediction/2024_Monsoon_Prep/run_classifier.py", line 192, in calc_model_performance
    wandb_id.log({
  File "/Users/kelseydoerksen/opt/anaconda3/envs/aq/lib/python3.10/bdb.py", line 90, in trace_dispatch
    return self.dispatch_line(frame)
  File "/Users/kelseydoerksen/opt/anaconda3/envs/aq/lib/python3.10/bdb.py", line 115, in dispatch_line
    if self.quitting: raise BdbQuit
bdb.BdbQuit
If you suspect this is an IPython 8.7.0 bug, please report it at:
    https://github.com/ipython/ipython/issues
or send an email to the mailing list at ipython-dev@python.org
You can print a more detailed traceback right now with "%tb", or use "%debug"
to interactively debug it.
Extra-detailed tracebacks for bug-reporting purposes can be enabled via:
    %config Application.verbose_crash=True