Testing pre-trained model on latest Monsoon season...
Grabbing testing data...
/Users/kelseydoerksen/opt/anaconda3/envs/aq/lib/python3.10/site-packages/osgeo/gdal.py:312: FutureWarning: Neither gdal.UseExceptions() nor gdal.DontUseExceptions() has been explicitly called. In GDAL 4.0, exceptions will be enabled by default.
  warnings.warn(
test set BCE is: 0.1076115071773529