Loading data...
Fitting model...
Evaluating model...
The hard predictions were right 85.25% of the time
> /Users/kelseydoerksen/code/landslide-prediction/2024_Monsoon_Prep/run_classifier.py(372)run_rf()
    371     # Plot roc_auc curve
--> 372     roc_auc(ytest, probs, results)
    373
array([0.95975702, 0.96507213, 0.95596052, 0.95444191, 0.96127563,
       0.96051632, 0.96279423, 0.96428571, 0.96884498, 0.96580547])
array([0.96089598, 0.95064541, 0.95290543, 0.95898215, 0.96619825])
array([0.89619025, 0.89565113, 0.89523182, 0.89450668, 0.89378782])
*** KeyError: 'train_accuracy'
{'fit_time': array([5.34173012, 1.74720907, 1.82614398, 1.76234198, 1.78624105,
       1.79792786, 1.78513002, 1.81325984, 1.79535103, 1.75382376]), 'score_time': array([0.05759597, 0.06507802, 0.06046319, 0.05707288, 0.05657697,
       0.05658102, 0.06532097, 0.06008315, 0.06817579, 0.05951309]), 'test_accuracy': array([0.95975702, 0.96507213, 0.95596052, 0.95444191, 0.96127563,
       0.96051632, 0.96279423, 0.96428571, 0.96884498, 0.96580547]), 'test_f1': array([0.84985836, 0.87222222, 0.83040936, 0.82954545, 0.85552408,
       0.85555556, 0.86648501, 0.86834734, 0.88515406, 0.87394958])}
*** KeyError: 'train_score'
Traceback (most recent call last):
  File "/Users/kelseydoerksen/code/landslide-prediction/2024_Monsoon_Prep/run_classifier.py", line 627, in <module>
  File "/Users/kelseydoerksen/code/landslide-prediction/2024_Monsoon_Prep/run_classifier.py", line 372, in run_rf
  File "/Users/kelseydoerksen/code/landslide-prediction/2024_Monsoon_Prep/run_classifier.py", line 372, in run_rf
  File "/Users/kelseydoerksen/opt/anaconda3/envs/aq/lib/python3.10/bdb.py", line 90, in trace_dispatch
    return self.dispatch_line(frame)
  File "/Users/kelseydoerksen/opt/anaconda3/envs/aq/lib/python3.10/bdb.py", line 115, in dispatch_line
    if self.quitting: raise BdbQuit
bdb.BdbQuit
If you suspect this is an IPython 8.7.0 bug, please report it at:
    https://github.com/ipython/ipython/issues
or send an email to the mailing list at ipython-dev@python.org
You can print a more detailed traceback right now with "%tb", or use "%debug"
to interactively debug it.
Extra-detailed tracebacks for bug-reporting purposes can be enabled via:
    %config Application.verbose_crash=True