/Users/kelseydoerksen/opt/anaconda3/envs/aq/lib/python3.10/site-packages/osgeo/gdal.py:312: FutureWarning: Neither gdal.UseExceptions() nor gdal.DontUseExceptions() has been explicitly called. In GDAL 4.0, exceptions will be enabled by default.
  warnings.warn(
Testing pre-trained model on latest Monsoon season...
Grabbing testing data...
Predicting on 2024 Monsoon season...
length of test dataset is: 18
> /Users/kelseydoerksen/code/landslide-forecast-nepal/unet/dataset.py(92)__getitem__()
     91
---> 92         image_fn = image_fns[index]
     93         label_fn = label_fns[index]
'/Volumes/PRO-G40/landslides/Nepal_Landslides_Forecasting_Project/Monsoon2024_Prep/2024_Season_Retro/Binary_Landslide_Labels_14day/label_2024-04-14.npy'
(60, 100)
<matplotlib.image.AxesImage object at 0x12b753e80>
Traceback (most recent call last):
  File "/Users/kelseydoerksen/code/landslide-forecast-nepal/unet/run_pipeline.py", line 149, in <module>
    predict(unet, landslide_test_dataset, experiment, save_dir, device=device,
  File "/Users/kelseydoerksen/code/landslide-forecast-nepal/unet/predict.py", line 46, in predict
    for i, data in enumerate(test_loader):
  File "/Users/kelseydoerksen/opt/anaconda3/envs/aq/lib/python3.10/site-packages/torch/utils/data/dataloader.py", line 633, in __next__
    data = self._next_data()
  File "/Users/kelseydoerksen/opt/anaconda3/envs/aq/lib/python3.10/site-packages/torch/utils/data/dataloader.py", line 677, in _next_data
    data = self._dataset_fetcher.fetch(index)  # may raise StopIteration
  File "/Users/kelseydoerksen/opt/anaconda3/envs/aq/lib/python3.10/site-packages/torch/utils/data/_utils/fetch.py", line 51, in fetch
    data = [self.dataset[idx] for idx in possibly_batched_index]
  File "/Users/kelseydoerksen/opt/anaconda3/envs/aq/lib/python3.10/site-packages/torch/utils/data/_utils/fetch.py", line 51, in <listcomp>
    data = [self.dataset[idx] for idx in possibly_batched_index]
  File "/Users/kelseydoerksen/code/landslide-forecast-nepal/unet/dataset.py", line 92, in __getitem__
    image_fn = image_fns[index]
  File "/Users/kelseydoerksen/code/landslide-forecast-nepal/unet/dataset.py", line 92, in __getitem__
    image_fn = image_fns[index]
  File "/Users/kelseydoerksen/opt/anaconda3/envs/aq/lib/python3.10/bdb.py", line 90, in trace_dispatch
    return self.dispatch_line(frame)
  File "/Users/kelseydoerksen/opt/anaconda3/envs/aq/lib/python3.10/bdb.py", line 115, in dispatch_line
    if self.quitting: raise BdbQuit
bdb.BdbQuit
If you suspect this is an IPython 8.7.0 bug, please report it at:
    https://github.com/ipython/ipython/issues
or send an email to the mailing list at ipython-dev@python.org
You can print a more detailed traceback right now with "%tb", or use "%debug"
to interactively debug it.
Extra-detailed tracebacks for bug-reporting purposes can be enabled via:
    %config Application.verbose_crash=True